[2025-07-06T17:32:52.459+0000] {taskinstance.py:1103} INFO - Dependencies all met for dep_context=non-requeueable deps ti=<TaskInstance: customer_activity_analysis.transform_data manual__2025-07-06T17:22:42.736917+00:00 [queued]>
[2025-07-06T17:32:52.466+0000] {taskinstance.py:1103} INFO - Dependencies all met for dep_context=requeueable deps ti=<TaskInstance: customer_activity_analysis.transform_data manual__2025-07-06T17:22:42.736917+00:00 [queued]>
[2025-07-06T17:32:52.466+0000] {taskinstance.py:1308} INFO - Starting attempt 2 of 2
[2025-07-06T17:32:52.478+0000] {taskinstance.py:1327} INFO - Executing <Task(PythonOperator): transform_data> on 2025-07-06 17:22:42.736917+00:00
[2025-07-06T17:32:52.487+0000] {standard_task_runner.py:57} INFO - Started process 1217 to run task
[2025-07-06T17:32:52.490+0000] {standard_task_runner.py:84} INFO - Running: ['***', 'tasks', 'run', 'customer_activity_analysis', 'transform_data', 'manual__2025-07-06T17:22:42.736917+00:00', '--job-id', '35', '--raw', '--subdir', 'DAGS_FOLDER/customer_activity_dag.py', '--cfg-path', '/tmp/tmpqqsp4_55']
[2025-07-06T17:32:52.491+0000] {standard_task_runner.py:85} INFO - Job 35: Subtask transform_data
[2025-07-06T17:32:52.504+0000] {logging_mixin.py:150} WARNING - /home/***/.local/lib/python3.7/site-packages/***/settings.py:195 DeprecationWarning: The sql_alchemy_conn option in [core] has been moved to the sql_alchemy_conn option in [database] - the old setting has been used, but please update your config.
[2025-07-06T17:32:52.534+0000] {task_command.py:410} INFO - Running <TaskInstance: customer_activity_analysis.transform_data manual__2025-07-06T17:22:42.736917+00:00 [running]> on host c00985d5f7a4
[2025-07-06T17:32:52.600+0000] {taskinstance.py:1547} INFO - Exporting env vars: AIRFLOW_CTX_DAG_EMAIL='ds_const@mail.ru' AIRFLOW_CTX_DAG_OWNER='Daniil' AIRFLOW_CTX_DAG_ID='customer_activity_analysis' AIRFLOW_CTX_TASK_ID='transform_data' AIRFLOW_CTX_EXECUTION_DATE='2025-07-06T17:22:42.736917+00:00' AIRFLOW_CTX_TRY_NUMBER='2' AIRFLOW_CTX_DAG_RUN_ID='manual__2025-07-06T17:22:42.736917+00:00'
[2025-07-06T17:32:53.414+0000] {logging_mixin.py:150} WARNING - TypeError: cannot construct a FileSource from               id         sum_a  sum_b  ...  count_i  count_j        date
0        C00313K      0.000000   8.77  ...      0.0      0.0  2023-10-01
1        C11256K      1.280000   0.00  ...      0.0      0.0  2023-10-01
2        C11256K      0.960000   0.00  ...      0.0      0.0  2023-11-01
3        C11256K      0.640000   0.00  ...      0.0      0.0  2024-01-01
4        C11256K      0.570000   0.00  ...      0.0      0.0  2024-02-01
...          ...           ...    ...  ...      ...      ...         ...
1270559  CBZYP6K  11955.375426   0.00  ...      0.0      0.0  2023-11-01
1270560  CBZYP6K  15788.860118   0.00  ...      0.0      0.0  2024-01-01
1270561  CBZYP6K  10987.337202   0.00  ...      0.0      0.0  2024-02-01
1270562  CBZYP6K  12158.722219   0.00  ...      0.0      0.0  2024-03-01
1270563  CBZYP6K  11897.703873   0.00  ...      0.0      0.0  2023-12-01

[1270564 rows x 22 columns]
[2025-07-06T17:32:53.414+0000] {logging_mixin.py:150} WARNING - Exception ignored in: 'pyarrow._dataset._make_file_source'
[2025-07-06T17:32:53.414+0000] {logging_mixin.py:150} WARNING - TypeError: cannot construct a FileSource from               id         sum_a  sum_b  ...  count_i  count_j        date
0        C00313K      0.000000   8.77  ...      0.0      0.0  2023-10-01
1        C11256K      1.280000   0.00  ...      0.0      0.0  2023-10-01
2        C11256K      0.960000   0.00  ...      0.0      0.0  2023-11-01
3        C11256K      0.640000   0.00  ...      0.0      0.0  2024-01-01
4        C11256K      0.570000   0.00  ...      0.0      0.0  2024-02-01
...          ...           ...    ...  ...      ...      ...         ...
1270559  CBZYP6K  11955.375426   0.00  ...      0.0      0.0  2023-11-01
1270560  CBZYP6K  15788.860118   0.00  ...      0.0      0.0  2024-01-01
1270561  CBZYP6K  10987.337202   0.00  ...      0.0      0.0  2024-02-01
1270562  CBZYP6K  12158.722219   0.00  ...      0.0      0.0  2024-03-01
1270563  CBZYP6K  11897.703873   0.00  ...      0.0      0.0  2023-12-01

[1270564 rows x 22 columns]
[2025-07-06T17:32:53.414+0000] {logging_mixin.py:150} INFO - Error in transform_data: Called Open() on an uninitialized FileSource
[2025-07-06T17:32:53.414+0000] {taskinstance.py:1824} ERROR - Task failed with exception
Traceback (most recent call last):
  File "/opt/airflow/dags/customer_activity_dag.py", line 93, in transform_data
    df = pd.read_parquet(tmp_path)
  File "/home/airflow/.local/lib/python3.7/site-packages/pandas/io/parquet.py", line 500, in read_parquet
    **kwargs,
  File "/home/airflow/.local/lib/python3.7/site-packages/pandas/io/parquet.py", line 240, in read
    path_or_handle, columns=columns, **kwargs
  File "/home/airflow/.local/lib/python3.7/site-packages/pyarrow/parquet/core.py", line 2939, in read_table
    thrift_container_size_limit=thrift_container_size_limit,
  File "/home/airflow/.local/lib/python3.7/site-packages/pyarrow/parquet/core.py", line 2466, in __init__
    [fragment], schema=schema or fragment.physical_schema,
  File "pyarrow/_dataset.pyx", line 1004, in pyarrow._dataset.Fragment.physical_schema.__get__
  File "pyarrow/error.pxi", line 144, in pyarrow.lib.pyarrow_internal_check_status
  File "pyarrow/error.pxi", line 100, in pyarrow.lib.check_status
pyarrow.lib.ArrowInvalid: Called Open() on an uninitialized FileSource

During handling of the above exception, another exception occurred:

Traceback (most recent call last):
  File "/home/airflow/.local/lib/python3.7/site-packages/airflow/operators/python.py", line 181, in execute
    return_value = self.execute_callable()
  File "/home/airflow/.local/lib/python3.7/site-packages/airflow/operators/python.py", line 198, in execute_callable
    return self.python_callable(*self.op_args, **self.op_kwargs)
  File "/opt/airflow/dags/customer_activity_dag.py", line 112, in transform_data
    if tmp_path and os.path.exists(tmp_path):
  File "/home/airflow/.local/lib/python3.7/site-packages/pandas/core/generic.py", line 1538, in __nonzero__
    f"The truth value of a {type(self).__name__} is ambiguous. "
ValueError: The truth value of a DataFrame is ambiguous. Use a.empty, a.bool(), a.item(), a.any() or a.all().
[2025-07-06T17:32:53.427+0000] {taskinstance.py:1350} INFO - Marking task as FAILED. dag_id=customer_activity_analysis, task_id=transform_data, execution_date=20250706T172242, start_date=20250706T173252, end_date=20250706T173253
[2025-07-06T17:32:53.442+0000] {standard_task_runner.py:109} ERROR - Failed to execute job 35 for task transform_data (The truth value of a DataFrame is ambiguous. Use a.empty, a.bool(), a.item(), a.any() or a.all().; 1217)
[2025-07-06T17:32:53.506+0000] {local_task_job_runner.py:225} INFO - Task exited with return code 1
[2025-07-06T17:32:53.531+0000] {taskinstance.py:2653} INFO - 0 downstream tasks scheduled from follow-on schedule check
