[2025-07-07T19:20:54.866+0000] {taskinstance.py:1103} INFO - Dependencies all met for dep_context=non-requeueable deps ti=<TaskInstance: customer_activity_analysis.load_data manual__2025-07-07T19:15:40.039325+00:00 [queued]>
[2025-07-07T19:20:54.872+0000] {taskinstance.py:1103} INFO - Dependencies all met for dep_context=requeueable deps ti=<TaskInstance: customer_activity_analysis.load_data manual__2025-07-07T19:15:40.039325+00:00 [queued]>
[2025-07-07T19:20:54.873+0000] {taskinstance.py:1308} INFO - Starting attempt 2 of 2
[2025-07-07T19:20:54.885+0000] {taskinstance.py:1327} INFO - Executing <Task(PythonOperator): load_data> on 2025-07-07 19:15:40.039325+00:00
[2025-07-07T19:20:54.893+0000] {standard_task_runner.py:57} INFO - Started process 945 to run task
[2025-07-07T19:20:54.895+0000] {standard_task_runner.py:84} INFO - Running: ['***', 'tasks', 'run', 'customer_activity_analysis', 'load_data', 'manual__2025-07-07T19:15:40.039325+00:00', '--job-id', '30', '--raw', '--subdir', 'DAGS_FOLDER/customer_activity_dag.py', '--cfg-path', '/tmp/tmp1qrzjo1h']
[2025-07-07T19:20:54.897+0000] {standard_task_runner.py:85} INFO - Job 30: Subtask load_data
[2025-07-07T19:20:54.909+0000] {logging_mixin.py:150} WARNING - /home/***/.local/lib/python3.7/site-packages/***/settings.py:195 DeprecationWarning: The sql_alchemy_conn option in [core] has been moved to the sql_alchemy_conn option in [database] - the old setting has been used, but please update your config.
[2025-07-07T19:20:54.933+0000] {task_command.py:410} INFO - Running <TaskInstance: customer_activity_analysis.load_data manual__2025-07-07T19:15:40.039325+00:00 [running]> on host 7a17032e36f4
[2025-07-07T19:20:55.117+0000] {taskinstance.py:1547} INFO - Exporting env vars: AIRFLOW_CTX_DAG_EMAIL='ds_const@mail.ru' AIRFLOW_CTX_DAG_OWNER='Daniil' AIRFLOW_CTX_DAG_ID='customer_activity_analysis' AIRFLOW_CTX_TASK_ID='load_data' AIRFLOW_CTX_EXECUTION_DATE='2025-07-07T19:15:40.039325+00:00' AIRFLOW_CTX_TRY_NUMBER='2' AIRFLOW_CTX_DAG_RUN_ID='manual__2025-07-07T19:15:40.039325+00:00'
[2025-07-07T19:20:55.126+0000] {taskinstance.py:1824} ERROR - Task failed with exception
Traceback (most recent call last):
  File "/home/airflow/.local/lib/python3.7/site-packages/airflow/operators/python.py", line 181, in execute
    return_value = self.execute_callable()
  File "/home/airflow/.local/lib/python3.7/site-packages/airflow/operators/python.py", line 198, in execute_callable
    return self.python_callable(*self.op_args, **self.op_kwargs)
  File "/opt/airflow/dags/customer_activity_dag.py", line 152, in load_data
    new_data = pd.read_csv(tmp_path)
  File "/home/airflow/.local/lib/python3.7/site-packages/pandas/util/_decorators.py", line 311, in wrapper
    return func(*args, **kwargs)
  File "/home/airflow/.local/lib/python3.7/site-packages/pandas/io/parsers/readers.py", line 586, in read_csv
    return _read(filepath_or_buffer, kwds)
  File "/home/airflow/.local/lib/python3.7/site-packages/pandas/io/parsers/readers.py", line 482, in _read
    parser = TextFileReader(filepath_or_buffer, **kwds)
  File "/home/airflow/.local/lib/python3.7/site-packages/pandas/io/parsers/readers.py", line 811, in __init__
    self._engine = self._make_engine(self.engine)
  File "/home/airflow/.local/lib/python3.7/site-packages/pandas/io/parsers/readers.py", line 1040, in _make_engine
    return mapping[engine](self.f, **self.options)  # type: ignore[call-arg]
  File "/home/airflow/.local/lib/python3.7/site-packages/pandas/io/parsers/c_parser_wrapper.py", line 51, in __init__
    self._open_handles(src, kwds)
  File "/home/airflow/.local/lib/python3.7/site-packages/pandas/io/parsers/base_parser.py", line 229, in _open_handles
    errors=kwds.get("encoding_errors", "strict"),
  File "/home/airflow/.local/lib/python3.7/site-packages/pandas/io/common.py", line 707, in get_handle
    newline="",
FileNotFoundError: [Errno 2] No such file or directory: '/opt/airflow/shared_tmp/transform_manual__2025-07-07T19:15:40.039325+00:00.parquet'
[2025-07-07T19:20:55.134+0000] {taskinstance.py:1350} INFO - Marking task as FAILED. dag_id=customer_activity_analysis, task_id=load_data, execution_date=20250707T191540, start_date=20250707T192054, end_date=20250707T192055
[2025-07-07T19:20:55.143+0000] {standard_task_runner.py:109} ERROR - Failed to execute job 30 for task load_data ([Errno 2] No such file or directory: '/opt/airflow/shared_tmp/transform_manual__2025-07-07T19:15:40.039325+00:00.parquet'; 945)
[2025-07-07T19:20:55.187+0000] {local_task_job_runner.py:225} INFO - Task exited with return code 1
[2025-07-07T19:20:55.206+0000] {taskinstance.py:2653} INFO - 0 downstream tasks scheduled from follow-on schedule check
