[2025-07-06T17:20:17.931+0000] {taskinstance.py:1103} INFO - Dependencies all met for dep_context=non-requeueable deps ti=<TaskInstance: customer_activity_analysis.extract_data manual__2025-07-06T17:20:16.502641+00:00 [queued]>
[2025-07-06T17:20:17.936+0000] {taskinstance.py:1103} INFO - Dependencies all met for dep_context=requeueable deps ti=<TaskInstance: customer_activity_analysis.extract_data manual__2025-07-06T17:20:16.502641+00:00 [queued]>
[2025-07-06T17:20:17.936+0000] {taskinstance.py:1308} INFO - Starting attempt 1 of 2
[2025-07-06T17:20:17.947+0000] {taskinstance.py:1327} INFO - Executing <Task(PythonOperator): extract_data> on 2025-07-06 17:20:16.502641+00:00
[2025-07-06T17:20:17.956+0000] {standard_task_runner.py:57} INFO - Started process 790 to run task
[2025-07-06T17:20:17.958+0000] {standard_task_runner.py:84} INFO - Running: ['***', 'tasks', 'run', 'customer_activity_analysis', 'extract_data', 'manual__2025-07-06T17:20:16.502641+00:00', '--job-id', '25', '--raw', '--subdir', 'DAGS_FOLDER/customer_activity_dag.py', '--cfg-path', '/tmp/tmpfd65ijka']
[2025-07-06T17:20:17.959+0000] {standard_task_runner.py:85} INFO - Job 25: Subtask extract_data
[2025-07-06T17:20:17.971+0000] {logging_mixin.py:150} WARNING - /home/***/.local/lib/python3.7/site-packages/***/settings.py:195 DeprecationWarning: The sql_alchemy_conn option in [core] has been moved to the sql_alchemy_conn option in [database] - the old setting has been used, but please update your config.
[2025-07-06T17:20:17.998+0000] {task_command.py:410} INFO - Running <TaskInstance: customer_activity_analysis.extract_data manual__2025-07-06T17:20:16.502641+00:00 [running]> on host c00985d5f7a4
[2025-07-06T17:20:18.061+0000] {taskinstance.py:1547} INFO - Exporting env vars: AIRFLOW_CTX_DAG_EMAIL='ds_const@mail.ru' AIRFLOW_CTX_DAG_OWNER='Daniil' AIRFLOW_CTX_DAG_ID='customer_activity_analysis' AIRFLOW_CTX_TASK_ID='extract_data' AIRFLOW_CTX_EXECUTION_DATE='2025-07-06T17:20:16.502641+00:00' AIRFLOW_CTX_TRY_NUMBER='1' AIRFLOW_CTX_DAG_RUN_ID='manual__2025-07-06T17:20:16.502641+00:00'
[2025-07-06T17:20:18.062+0000] {taskinstance.py:1824} ERROR - Task failed with exception
Traceback (most recent call last):
  File "/home/airflow/.local/lib/python3.7/site-packages/airflow/operators/python.py", line 181, in execute
    return_value = self.execute_callable()
  File "/home/airflow/.local/lib/python3.7/site-packages/airflow/operators/python.py", line 198, in execute_callable
    return self.python_callable(*self.op_args, **self.op_kwargs)
  File "/opt/airflow/dags/customer_activity_dag.py", line 75, in extract_data
    if df.memory_usage().sum() > 45000:
UnboundLocalError: local variable 'df' referenced before assignment
[2025-07-06T17:20:18.068+0000] {taskinstance.py:1350} INFO - Marking task as UP_FOR_RETRY. dag_id=customer_activity_analysis, task_id=extract_data, execution_date=20250706T172016, start_date=20250706T172017, end_date=20250706T172018
[2025-07-06T17:20:18.076+0000] {standard_task_runner.py:109} ERROR - Failed to execute job 25 for task extract_data (local variable 'df' referenced before assignment; 790)
[2025-07-06T17:20:18.089+0000] {local_task_job_runner.py:225} INFO - Task exited with return code 1
[2025-07-06T17:20:18.109+0000] {taskinstance.py:2653} INFO - 0 downstream tasks scheduled from follow-on schedule check
