[2025-07-06T17:40:57.626+0000] {taskinstance.py:1103} INFO - Dependencies all met for dep_context=non-requeueable deps ti=<TaskInstance: customer_activity_analysis.transform_data manual__2025-07-06T17:40:54.424161+00:00 [queued]>
[2025-07-06T17:40:57.632+0000] {taskinstance.py:1103} INFO - Dependencies all met for dep_context=requeueable deps ti=<TaskInstance: customer_activity_analysis.transform_data manual__2025-07-06T17:40:54.424161+00:00 [queued]>
[2025-07-06T17:40:57.632+0000] {taskinstance.py:1308} INFO - Starting attempt 1 of 2
[2025-07-06T17:40:57.644+0000] {taskinstance.py:1327} INFO - Executing <Task(PythonOperator): transform_data> on 2025-07-06 17:40:54.424161+00:00
[2025-07-06T17:40:57.655+0000] {standard_task_runner.py:57} INFO - Started process 1488 to run task
[2025-07-06T17:40:57.658+0000] {standard_task_runner.py:84} INFO - Running: ['***', 'tasks', 'run', 'customer_activity_analysis', 'transform_data', 'manual__2025-07-06T17:40:54.424161+00:00', '--job-id', '43', '--raw', '--subdir', 'DAGS_FOLDER/customer_activity_dag.py', '--cfg-path', '/tmp/tmpw0reah7j']
[2025-07-06T17:40:57.659+0000] {standard_task_runner.py:85} INFO - Job 43: Subtask transform_data
[2025-07-06T17:40:57.672+0000] {logging_mixin.py:150} WARNING - /home/***/.local/lib/python3.7/site-packages/***/settings.py:195 DeprecationWarning: The sql_alchemy_conn option in [core] has been moved to the sql_alchemy_conn option in [database] - the old setting has been used, but please update your config.
[2025-07-06T17:40:57.705+0000] {task_command.py:410} INFO - Running <TaskInstance: customer_activity_analysis.transform_data manual__2025-07-06T17:40:54.424161+00:00 [running]> on host c00985d5f7a4
[2025-07-06T17:40:57.775+0000] {taskinstance.py:1547} INFO - Exporting env vars: AIRFLOW_CTX_DAG_EMAIL='ds_const@mail.ru' AIRFLOW_CTX_DAG_OWNER='Daniil' AIRFLOW_CTX_DAG_ID='customer_activity_analysis' AIRFLOW_CTX_TASK_ID='transform_data' AIRFLOW_CTX_EXECUTION_DATE='2025-07-06T17:40:54.424161+00:00' AIRFLOW_CTX_TRY_NUMBER='1' AIRFLOW_CTX_DAG_RUN_ID='manual__2025-07-06T17:40:54.424161+00:00'
[2025-07-06T17:40:57.968+0000] {logging_mixin.py:150} INFO - Data loaded from temp file. Shape: (1270564, 22)
[2025-07-06T17:40:57.968+0000] {logging_mixin.py:150} INFO - Error in transform_data: local variable 'tmp' referenced before assignment
[2025-07-06T17:40:57.971+0000] {taskinstance.py:1824} ERROR - Task failed with exception
Traceback (most recent call last):
  File "/home/airflow/.local/lib/python3.7/site-packages/airflow/operators/python.py", line 181, in execute
    return_value = self.execute_callable()
  File "/home/airflow/.local/lib/python3.7/site-packages/airflow/operators/python.py", line 198, in execute_callable
    return self.python_callable(*self.op_args, **self.op_kwargs)
  File "/opt/airflow/dags/customer_activity_dag.py", line 97, in transform_data
    print(f"#########################{tmp.name}")
UnboundLocalError: local variable 'tmp' referenced before assignment
[2025-07-06T17:40:57.977+0000] {taskinstance.py:1350} INFO - Marking task as UP_FOR_RETRY. dag_id=customer_activity_analysis, task_id=transform_data, execution_date=20250706T174054, start_date=20250706T174057, end_date=20250706T174057
[2025-07-06T17:40:57.987+0000] {standard_task_runner.py:109} ERROR - Failed to execute job 43 for task transform_data (local variable 'tmp' referenced before assignment; 1488)
[2025-07-06T17:40:58.070+0000] {local_task_job_runner.py:225} INFO - Task exited with return code 1
[2025-07-06T17:40:58.094+0000] {taskinstance.py:2653} INFO - 0 downstream tasks scheduled from follow-on schedule check
