[2025-07-07T19:46:44.440+0000] {taskinstance.py:1103} INFO - Dependencies all met for dep_context=non-requeueable deps ti=<TaskInstance: customer_activity_analysis.load_data manual__2025-07-07T19:41:29.094337+00:00 [queued]>
[2025-07-07T19:46:44.446+0000] {taskinstance.py:1103} INFO - Dependencies all met for dep_context=requeueable deps ti=<TaskInstance: customer_activity_analysis.load_data manual__2025-07-07T19:41:29.094337+00:00 [queued]>
[2025-07-07T19:46:44.446+0000] {taskinstance.py:1308} INFO - Starting attempt 2 of 2
[2025-07-07T19:46:44.458+0000] {taskinstance.py:1327} INFO - Executing <Task(PythonOperator): load_data> on 2025-07-07 19:41:29.094337+00:00
[2025-07-07T19:46:44.466+0000] {standard_task_runner.py:57} INFO - Started process 1566 to run task
[2025-07-07T19:46:44.469+0000] {standard_task_runner.py:84} INFO - Running: ['***', 'tasks', 'run', 'customer_activity_analysis', 'load_data', 'manual__2025-07-07T19:41:29.094337+00:00', '--job-id', '52', '--raw', '--subdir', 'DAGS_FOLDER/customer_activity_dag.py', '--cfg-path', '/tmp/tmp7chhg45j']
[2025-07-07T19:46:44.471+0000] {standard_task_runner.py:85} INFO - Job 52: Subtask load_data
[2025-07-07T19:46:44.485+0000] {logging_mixin.py:150} WARNING - /home/***/.local/lib/python3.7/site-packages/***/settings.py:195 DeprecationWarning: The sql_alchemy_conn option in [core] has been moved to the sql_alchemy_conn option in [database] - the old setting has been used, but please update your config.
[2025-07-07T19:46:44.514+0000] {task_command.py:410} INFO - Running <TaskInstance: customer_activity_analysis.load_data manual__2025-07-07T19:41:29.094337+00:00 [running]> on host 7a17032e36f4
[2025-07-07T19:46:44.714+0000] {taskinstance.py:1547} INFO - Exporting env vars: AIRFLOW_CTX_DAG_EMAIL='ds_const@mail.ru' AIRFLOW_CTX_DAG_OWNER='Daniil' AIRFLOW_CTX_DAG_ID='customer_activity_analysis' AIRFLOW_CTX_TASK_ID='load_data' AIRFLOW_CTX_EXECUTION_DATE='2025-07-07T19:41:29.094337+00:00' AIRFLOW_CTX_TRY_NUMBER='2' AIRFLOW_CTX_DAG_RUN_ID='manual__2025-07-07T19:41:29.094337+00:00'
[2025-07-07T19:46:44.724+0000] {logging_mixin.py:150} INFO - Error in load_data: [Errno 2] No such file or directory: '/opt/***/shared_tmp/transform_manual__2025-07-07T19:41:29.094337+00:00.csv'
[2025-07-07T19:46:44.724+0000] {taskinstance.py:1824} ERROR - Task failed with exception
Traceback (most recent call last):
  File "/opt/airflow/dags/customer_activity_dag.py", line 150, in load_data
    new_data = pd.read_csv(tmp_path)
  File "/home/airflow/.local/lib/python3.7/site-packages/pandas/util/_decorators.py", line 311, in wrapper
    return func(*args, **kwargs)
  File "/home/airflow/.local/lib/python3.7/site-packages/pandas/io/parsers/readers.py", line 586, in read_csv
    return _read(filepath_or_buffer, kwds)
  File "/home/airflow/.local/lib/python3.7/site-packages/pandas/io/parsers/readers.py", line 482, in _read
    parser = TextFileReader(filepath_or_buffer, **kwds)
  File "/home/airflow/.local/lib/python3.7/site-packages/pandas/io/parsers/readers.py", line 811, in __init__
    self._engine = self._make_engine(self.engine)
  File "/home/airflow/.local/lib/python3.7/site-packages/pandas/io/parsers/readers.py", line 1040, in _make_engine
    return mapping[engine](self.f, **self.options)  # type: ignore[call-arg]
  File "/home/airflow/.local/lib/python3.7/site-packages/pandas/io/parsers/c_parser_wrapper.py", line 51, in __init__
    self._open_handles(src, kwds)
  File "/home/airflow/.local/lib/python3.7/site-packages/pandas/io/parsers/base_parser.py", line 229, in _open_handles
    errors=kwds.get("encoding_errors", "strict"),
  File "/home/airflow/.local/lib/python3.7/site-packages/pandas/io/common.py", line 707, in get_handle
    newline="",
FileNotFoundError: [Errno 2] No such file or directory: '/opt/airflow/shared_tmp/transform_manual__2025-07-07T19:41:29.094337+00:00.csv'

During handling of the above exception, another exception occurred:

Traceback (most recent call last):
  File "/home/airflow/.local/lib/python3.7/site-packages/airflow/operators/python.py", line 181, in execute
    return_value = self.execute_callable()
  File "/home/airflow/.local/lib/python3.7/site-packages/airflow/operators/python.py", line 198, in execute_callable
    return self.python_callable(*self.op_args, **self.op_kwargs)
  File "/opt/airflow/dags/customer_activity_dag.py", line 183, in load_data
    new_data.to_csv(error_path, index=False)
UnboundLocalError: local variable 'new_data' referenced before assignment
[2025-07-07T19:46:44.732+0000] {taskinstance.py:1350} INFO - Marking task as FAILED. dag_id=customer_activity_analysis, task_id=load_data, execution_date=20250707T194129, start_date=20250707T194644, end_date=20250707T194644
[2025-07-07T19:46:44.743+0000] {standard_task_runner.py:109} ERROR - Failed to execute job 52 for task load_data (local variable 'new_data' referenced before assignment; 1566)
[2025-07-07T19:46:44.761+0000] {local_task_job_runner.py:225} INFO - Task exited with return code 1
[2025-07-07T19:46:44.776+0000] {taskinstance.py:2653} INFO - 0 downstream tasks scheduled from follow-on schedule check
