[2025-07-06T18:48:44.528+0000] {taskinstance.py:1103} INFO - Dependencies all met for dep_context=non-requeueable deps ti=<TaskInstance: customer_activity_analysis.transform_data manual__2025-07-06T18:43:38.971106+00:00 [queued]>
[2025-07-06T18:48:44.533+0000] {taskinstance.py:1103} INFO - Dependencies all met for dep_context=requeueable deps ti=<TaskInstance: customer_activity_analysis.transform_data manual__2025-07-06T18:43:38.971106+00:00 [queued]>
[2025-07-06T18:48:44.533+0000] {taskinstance.py:1308} INFO - Starting attempt 2 of 2
[2025-07-06T18:48:44.545+0000] {taskinstance.py:1327} INFO - Executing <Task(PythonOperator): transform_data> on 2025-07-06 18:43:38.971106+00:00
[2025-07-06T18:48:44.553+0000] {standard_task_runner.py:57} INFO - Started process 265 to run task
[2025-07-06T18:48:44.556+0000] {standard_task_runner.py:84} INFO - Running: ['***', 'tasks', 'run', 'customer_activity_analysis', 'transform_data', 'manual__2025-07-06T18:43:38.971106+00:00', '--job-id', '59', '--raw', '--subdir', 'DAGS_FOLDER/customer_activity_dag.py', '--cfg-path', '/tmp/tmp30ah7emc']
[2025-07-06T18:48:44.557+0000] {standard_task_runner.py:85} INFO - Job 59: Subtask transform_data
[2025-07-06T18:48:44.570+0000] {logging_mixin.py:150} WARNING - /home/***/.local/lib/python3.7/site-packages/***/settings.py:195 DeprecationWarning: The sql_alchemy_conn option in [core] has been moved to the sql_alchemy_conn option in [database] - the old setting has been used, but please update your config.
[2025-07-06T18:48:44.596+0000] {task_command.py:410} INFO - Running <TaskInstance: customer_activity_analysis.transform_data manual__2025-07-06T18:43:38.971106+00:00 [running]> on host 636fb1e40b9e
[2025-07-06T18:48:44.658+0000] {taskinstance.py:1547} INFO - Exporting env vars: AIRFLOW_CTX_DAG_EMAIL='ds_const@mail.ru' AIRFLOW_CTX_DAG_OWNER='Daniil' AIRFLOW_CTX_DAG_ID='customer_activity_analysis' AIRFLOW_CTX_TASK_ID='transform_data' AIRFLOW_CTX_EXECUTION_DATE='2025-07-06T18:43:38.971106+00:00' AIRFLOW_CTX_TRY_NUMBER='2' AIRFLOW_CTX_DAG_RUN_ID='manual__2025-07-06T18:43:38.971106+00:00'
[2025-07-06T18:48:44.667+0000] {logging_mixin.py:150} INFO - Ошибка в transform_data: Файл /opt/***/shared_tmp/extract_manual__2025-07-06T18:43:38.971106+00:00.parquet не найден
[2025-07-06T18:48:44.667+0000] {taskinstance.py:1824} ERROR - Task failed with exception
Traceback (most recent call last):
  File "/home/airflow/.local/lib/python3.7/site-packages/airflow/operators/python.py", line 181, in execute
    return_value = self.execute_callable()
  File "/home/airflow/.local/lib/python3.7/site-packages/airflow/operators/python.py", line 198, in execute_callable
    return self.python_callable(*self.op_args, **self.op_kwargs)
  File "/opt/airflow/dags/customer_activity_dag.py", line 99, in transform_data
    raise FileNotFoundError(f"Файл {input_path} не найден")
FileNotFoundError: Файл /opt/***/shared_tmp/extract_manual__2025-07-06T18:43:38.971106+00:00.parquet не найден
[2025-07-06T18:48:44.672+0000] {taskinstance.py:1350} INFO - Marking task as FAILED. dag_id=customer_activity_analysis, task_id=transform_data, execution_date=20250706T184338, start_date=20250706T184844, end_date=20250706T184844
[2025-07-06T18:48:44.682+0000] {standard_task_runner.py:109} ERROR - Failed to execute job 59 for task transform_data (Файл /opt/***/shared_tmp/extract_manual__2025-07-06T18:43:38.971106+00:00.parquet не найден; 265)
[2025-07-06T18:48:44.727+0000] {local_task_job_runner.py:225} INFO - Task exited with return code 1
[2025-07-06T18:48:44.748+0000] {taskinstance.py:2653} INFO - 0 downstream tasks scheduled from follow-on schedule check
