[2025-07-06T18:43:42.855+0000] {taskinstance.py:1103} INFO - Dependencies all met for dep_context=non-requeueable deps ti=<TaskInstance: customer_activity_analysis.transform_data manual__2025-07-06T18:43:38.971106+00:00 [queued]>
[2025-07-06T18:43:42.861+0000] {taskinstance.py:1103} INFO - Dependencies all met for dep_context=requeueable deps ti=<TaskInstance: customer_activity_analysis.transform_data manual__2025-07-06T18:43:38.971106+00:00 [queued]>
[2025-07-06T18:43:42.861+0000] {taskinstance.py:1308} INFO - Starting attempt 1 of 2
[2025-07-06T18:43:42.873+0000] {taskinstance.py:1327} INFO - Executing <Task(PythonOperator): transform_data> on 2025-07-06 18:43:38.971106+00:00
[2025-07-06T18:43:42.882+0000] {standard_task_runner.py:57} INFO - Started process 2884 to run task
[2025-07-06T18:43:42.884+0000] {standard_task_runner.py:84} INFO - Running: ['***', 'tasks', 'run', 'customer_activity_analysis', 'transform_data', 'manual__2025-07-06T18:43:38.971106+00:00', '--job-id', '54', '--raw', '--subdir', 'DAGS_FOLDER/customer_activity_dag.py', '--cfg-path', '/tmp/tmpkdopub3_']
[2025-07-06T18:43:42.886+0000] {standard_task_runner.py:85} INFO - Job 54: Subtask transform_data
[2025-07-06T18:43:42.899+0000] {logging_mixin.py:150} WARNING - /home/***/.local/lib/python3.7/site-packages/***/settings.py:195 DeprecationWarning: The sql_alchemy_conn option in [core] has been moved to the sql_alchemy_conn option in [database] - the old setting has been used, but please update your config.
[2025-07-06T18:43:42.926+0000] {task_command.py:410} INFO - Running <TaskInstance: customer_activity_analysis.transform_data manual__2025-07-06T18:43:38.971106+00:00 [running]> on host c00985d5f7a4
[2025-07-06T18:43:42.990+0000] {taskinstance.py:1547} INFO - Exporting env vars: AIRFLOW_CTX_DAG_EMAIL='ds_const@mail.ru' AIRFLOW_CTX_DAG_OWNER='Daniil' AIRFLOW_CTX_DAG_ID='customer_activity_analysis' AIRFLOW_CTX_TASK_ID='transform_data' AIRFLOW_CTX_EXECUTION_DATE='2025-07-06T18:43:38.971106+00:00' AIRFLOW_CTX_TRY_NUMBER='1' AIRFLOW_CTX_DAG_RUN_ID='manual__2025-07-06T18:43:38.971106+00:00'
[2025-07-06T18:43:43.183+0000] {logging_mixin.py:150} INFO - Received date type: <class 'str'>, value: 2025-07-06
[2025-07-06T18:43:43.220+0000] {logging_mixin.py:150} INFO - Debug data saved to /opt/***/data/debug_data.csv
[2025-07-06T18:43:43.223+0000] {logging_mixin.py:150} WARNING -   0%|          | 0/10 [00:00<?, ?it/s]
[2025-07-06T18:43:43.224+0000] {logging_mixin.py:150} WARNING -   0%|          | 0/10 [00:00<?, ?it/s]
[2025-07-06T18:43:43.224+0000] {logging_mixin.py:150} INFO - Ошибка в transform_data: Wrong number of items passed 20, placement implies 1
[2025-07-06T18:43:43.224+0000] {taskinstance.py:1824} ERROR - Task failed with exception
Traceback (most recent call last):
  File "/home/airflow/.local/lib/python3.7/site-packages/pandas/core/indexes/base.py", line 3361, in get_loc
    return self._engine.get_loc(casted_key)
  File "pandas/_libs/index.pyx", line 76, in pandas._libs.index.IndexEngine.get_loc
  File "pandas/_libs/index.pyx", line 108, in pandas._libs.index.IndexEngine.get_loc
  File "pandas/_libs/hashtable_class_helper.pxi", line 5198, in pandas._libs.hashtable.PyObjectHashTable.get_item
  File "pandas/_libs/hashtable_class_helper.pxi", line 5206, in pandas._libs.hashtable.PyObjectHashTable.get_item
KeyError: 'flag_a'

The above exception was the direct cause of the following exception:

Traceback (most recent call last):
  File "/home/airflow/.local/lib/python3.7/site-packages/pandas/core/frame.py", line 3751, in _set_item_mgr
    loc = self._info_axis.get_loc(key)
  File "/home/airflow/.local/lib/python3.7/site-packages/pandas/core/indexes/base.py", line 3363, in get_loc
    raise KeyError(key) from err
KeyError: 'flag_a'

During handling of the above exception, another exception occurred:

Traceback (most recent call last):
  File "/home/airflow/.local/lib/python3.7/site-packages/airflow/operators/python.py", line 181, in execute
    return_value = self.execute_callable()
  File "/home/airflow/.local/lib/python3.7/site-packages/airflow/operators/python.py", line 198, in execute_callable
    return self.python_callable(*self.op_args, **self.op_kwargs)
  File "/opt/airflow/dags/customer_activity_dag.py", line 105, in transform_data
    result = transform(df, kwargs['logical_date'].strftime('%Y-%m-%d'))
  File "/opt/airflow/dags/customer_activity_dag.py", line 63, in transform
    ).astype(int)
  File "/home/airflow/.local/lib/python3.7/site-packages/pandas/core/frame.py", line 3602, in __setitem__
    self._set_item_frame_value(key, value)
  File "/home/airflow/.local/lib/python3.7/site-packages/pandas/core/frame.py", line 3742, in _set_item_frame_value
    self._set_item_mgr(key, arraylike)
  File "/home/airflow/.local/lib/python3.7/site-packages/pandas/core/frame.py", line 3754, in _set_item_mgr
    self._mgr.insert(len(self._info_axis), key, value)
  File "/home/airflow/.local/lib/python3.7/site-packages/pandas/core/internals/managers.py", line 1162, in insert
    block = new_block(values=value, ndim=self.ndim, placement=slice(loc, loc + 1))
  File "/home/airflow/.local/lib/python3.7/site-packages/pandas/core/internals/blocks.py", line 1937, in new_block
    check_ndim(values, placement, ndim)
  File "/home/airflow/.local/lib/python3.7/site-packages/pandas/core/internals/blocks.py", line 1980, in check_ndim
    f"Wrong number of items passed {len(values)}, "
ValueError: Wrong number of items passed 20, placement implies 1
[2025-07-06T18:43:43.233+0000] {taskinstance.py:1350} INFO - Marking task as UP_FOR_RETRY. dag_id=customer_activity_analysis, task_id=transform_data, execution_date=20250706T184338, start_date=20250706T184342, end_date=20250706T184343
[2025-07-06T18:43:43.244+0000] {standard_task_runner.py:109} ERROR - Failed to execute job 54 for task transform_data (Wrong number of items passed 20, placement implies 1; 2884)
[2025-07-06T18:43:43.298+0000] {local_task_job_runner.py:225} INFO - Task exited with return code 1
[2025-07-06T18:43:43.319+0000] {taskinstance.py:2653} INFO - 0 downstream tasks scheduled from follow-on schedule check
